Workbook

Sheet 注文書
DR2: 様式第１
AJ3: 注 文 書
CT4: 令 和 | DA4: 23 | DG4: 年 | DO4: 月 | DV4: 日
C5: （下請負人） | CG5: （元請負人）
D8: 住所 | CG8: 住 所 | CS8: 長崎県長崎市多以良町1551番地93
EO9: 長崎県長崎市多以良町1551番地93
CS10: 株式会社Factory
EO11: 本 間 建 設 株 式 会 社
D12: 氏名 | CG12: 氏 名 | CS12: 代表取締役社長 山本 清和
EO13: 代表取締役社長 山本 清和
C14: （保 証 人） | CG14: （保 証 人）
D16: 住所 | CG16: 住 所
AO17: 御中
D18: 氏名 | CG18: 氏 名
C20: （保証人欄は、保証人を立てる場合に使用する） | CG20: （保証人欄は、保証人を立てる場合に使用する）
B23: 下記のとおり注文いたしますから、お引受の際は別紙注文請書をご提出下さい。なお、注文内容内訳はお見積書のとおりです。
B24: 下請負契約の場合、この注文書に記載のない条件については、別添の個別工事下請契約約款の定めによります。ただし、
B25: 立替払などがあるときは、工事支払金と相殺することがあります。なお、金額欄の工事価格には解体工事に要する費用及び
B26: 再資源化等に要する費用がある場合にはその費用を含みます。
B28: 物品の売買契約の場合は、裏面記載のとおりです。
B31: コード番号 | W31: 見 積 番 号 | AR31: 金 額 | CK31: 支 払 条 件
AW32: 請 負 代 金 額 | CF32: 円 | CK32: 前払金 | DF32: 円 | DJ32: 部分払 | DP32: 出来高・納入額の
B33: 注 文 内 容
DU35: 100 | DZ35: ％
B36: 件 名
AU37: うち 工 事 価 格
CK38: 部 分 払 | CR38: 現 金 | CX38: 100 | DC38: ％、 | DG38: 手形 | DK38: 0 | DO38: ％ | DQ38: （サイト | DU38: - | DZ38: 日）
AV40: =IF(AV34="","",AV34/1.1)
CK41: 完 成 払 | CR41: 現 金 | CX41: - | DC41: ％、 | DG41: 手形 | DK41: - | DO41: ％ | DQ41: （サイト | DU41: - | DZ41: 日）
AU43: 取引に係る消費税及び地方
CK44: 履行遅滞の | CW44: 年 | DB44: 0.03 | DJ44: 過 払 の | DS44: 年 | DV44: 3 | DY44: ％
AU46: 消費税の額
B48: 場 所
AV49: =IF(AV40="","",AV40*10%) | CK49: 遅延利息(注) | DB49: 0.146 | DJ49: 返還利息
CK52: 運 送 | DA52: 労 災 保 険 | DP52: 契約不適合
B53: 「建設工事に係る資材の再資源化等に関する法律」の対象建設工事に該当の有無 | AR53: □該当する | BO53: □該当しない
AR55: 該当する別紙(Ⅰ～Ⅲ)に記入する | CK55: 受注者 | CR55: 注文者 | DA55: 受注者 | DI55: 注文者 | DP55: 責任期間
B57: 工 期 ・ 納 期 | AR57: 請 求 締 切 | BO57: 支 払 | CK57: 負 担 | CR57: 負 担 | DA57: 加 入 | DI57: 加 入 | DP57: 工事目的物 2 年
B58: 至急・即納 | J58: （自）令和 年 月 日 （至）令和 年 月 日 | AR58: 毎月20日 | BO58: 現金：翌月末日 | CK58: ○ | DI58: ○
P59: ・ | T59: ・ | Z59: ～ | AG59: ・ | AJ59: ・ | DP59: 機器本体等 1 年
...

Sheet 注文請書
DS2: 様式第２
AK3: 注 文 請 書
CU4: 令 和 | DB4: 23 | DC4: =IFERROR(IF(注文書!DB4="","",注文書!DB4),"") | DH4: 年 | DL4: =IFERROR(IF(注文書!DK4="","",注文書!DK4),"") | DP4: 月 | DS4: =IFERROR(IF(注文書!DR4="","",注文書!DR4),"") | DW4: 日
C5: （下請負人） | CI5: （元請負人） | CT5: =IFERROR(IF(注文書!CS5="","",注文書!CS5),"")
CT7: =IFERROR(IF(注文書!CS7="","",注文書!CS7),"")
D8: 住所 | N8: =IFERROR(IF(注文書!N8="","",注文書!N8),"") | CH8: 住 所 | CT8: =注文書!CS8 -> 長崎県長崎市多以良町1551番地93
N10: =IFERROR(IF(注文書!N10="","",注文書!N10),"") | CT10: =注文書!CS10 -> 株式会社Factory
D12: 氏名 | N12: =IFERROR(IF(注文書!N12="","",注文書!N12),"") | CH12: 氏 名 | CT12: =注文書!CS12 -> 代表取締役社長 山本 清和
C14: （保 証 人） | CH14: （保 証 人）
D16: 住所 | CH16: 住 所 | CT16: =注文書!CS16 -> 0
DY17: 御中
D18: 氏名 | CH18: 氏 名 | CT18: =注文書!CS18 -> 0
C20: （保証人欄は、保証人を立てる場合に使用する） | CH20: （保証人欄は、保証人を立てる場合に使用する）
B23: 貴注文を下記条項承諾のうえお受けします。ただし、金額欄の工事価格には解体工事に要する費用及び再資源化等に要する
B24: 費用がある場合にはその費用を含みます。
B26: なお、この契約の履行に当たっては、別添の個別工事下請契約約款、裏面記載の物品の売買契約条件を遵守します。
B32: コード番号 | K32: =注文書!K31 -> 0 | W32: 見 積 番 号 | AF32: =注文書!AF31 -> 0 | AS32: =注文書!AR31 -> 金 額 | CL32: 支 払 条 件
AX33: 請 負 代 金 額 | CG33: 円 | CL33: 前払金 | DG33: 円 | DK33: 部分払 | DQ33: 出来高・納入額の
B34: 注 文 内 容
AW35: =IFERROR(IF(注文書!AV34="","",注文書!AV34),"")
DV36: =注文書!DU35 -> 100 | EA36: ％
B37: 件 名 | H37: =IFERROR(IF(注文書!G36="","",注文書!G36),"")
AV38: うち 工 事 価 格
CL39: 部 分 払 | CS39: 現 金 | CY39: =注文書!CX38 -> 100 | DD39: ％、 | DH39: 手形 | DL39: =注文書!DK38 -> 0 | DP39: ％ | DR39: （サイト | DV39: =注文書!DU38 -> - | EA39: 日）
AW41: =IFERROR(IF(注文書!AV40="","",注文書!AV40),"")
CL42: 完 成 払 | CS42: 現 金 | CY42: =注文書!CX41 -> - | DD42: ％、 | DH42: 手形 | DL42: =注文書!DK41 -> - | DP42: ％ | DR42: （サイト | DV42: =注文書!DU41 -> - | EA42: 日）
AV44: 取引に係る消費税及び地方
CL45: 履行遅滞の | CX45: 年 | DC45: =注文書!DB44 -> 0.03 | DK45: 過 払 の | DT45: 年 | DW45: =注文書!DV44 -> 3 | DZ45: ％
AV47: 消費税の額
B49: 場 所 | H49: =IFERROR(IF(注文書!G48="","",注文書!G48),"")
AW50: =IFERROR(IF(注文書!AV49="","",注文書!AV49),"") | CL50: 遅延利息(注) | DC50: 0.146 | DK50: 返還利息
CL53: 運 送 | DB53: 労 災 保 険 | DQ53: 契約不適合
B54: 「建設工事に係る資材の再資源化等に関する法律」の対象建設工事に該当の有無 | AS54: □該当する | BP54: □該当しない
AS56: 該当する別紙(Ⅰ～Ⅲ)に記入する | CL56: 受注者 | CS56: 注文者 | DB56: 受注者 | DJ56: 注文者 | DQ56: 責任期間
B58: 工 期 ・ 納 期 | AS58: 請 求 締 切 | BP58: 支 払 | CL58: 負 担 | CS58: 負 担 | DB58: 加 入 | DJ58: 加 入 | DQ58: 工事目的物 2 年
B59: 至急・即納 | K59: （自）令和 年 月 日 （至）令和 年 月 日 | AS59: =注文書!AR58 -> 毎月20日 | BP59: 現金：翌月末日 | CL59: =注文書!CK58 -> ○ | CS59: =注文書!CR58 -> 0 | DB59: =注文書!DA58 -> 0 | DJ59: =注文書!DI58 -> ○
Q60: ・ | U60: ・ | AA60: ～ | AH60: ・ | AK60: ・ | DQ60: 機器本体等 1 年
N61: =IFERROR(IF(注文書!M60="","",注文書!M60),"") | R61: =IFERROR(IF(注文書!Q60="","",注文書!Q60),"") | V61: =IFERROR(IF(注文書!U60="","",注文書!U60),"") | AF61: =IFERROR(IF(注文書!AE60="","",注文書!AE60),"") | AJ61: =IFERROR(IF(注文書!AI60="","",注文書!AI60),"") | AN61: =IFERROR(IF(注文書!AM60="","",注文書!AM60),"")
B62: (注) 特定建設業者でない個人又は資本の額が建設業法施工令第7条の2に定める金額未満の業者との契約の完成払いにおいては、完成検査に合格した日又は引渡しの日から起算して50日を
B63: 経過した日から率は14.6％とする〔建設業法第24条の5第4項〕。
...
